Workbook
Name LeadTypeList: Lists!$4:$4
Name SourceList: Lists!$3:$3
Name StageList: Lists!$A$1:$I$1
Name TypeList: Lists!$A$2:$F$2

Sheet Lists
A1: Round A | B1: Pre Seed | C1: TTOs | D1: Seed | E1: Startups Creation Platforms | F1: Ideation | G1: Growth/Large Company | H1: Other | I1: Human Capital Programs
A2: Email | B2: Call | C2: LinkedIn | D2: AIcademy Webinars | E2: Meeting | F2: Other
A3: רשהח"ד 2025 | B3: Webinars 2.26 | C3: יפעת | D3: Referral | E3: LinkedIn | F3: Website | G3: Conference | H3: Cold Outreach | I3: Partner | J3: AIcademy Webinars | K3: Other
A4: Lead | B4: Customer | C4: Past Customer | D4: Supplier | E4: Student | F4: Student Lead | G4: Contact | H4: Other

Sheet Next Actions
A1: NEAT CRM
A2: Next Actions
A3: # | B3: Date | C3: Contact Email | D3: Contact Name | E3: Company | F3: Type | G3: Subject / Topic | H3: Owner | I3: Next Action | J3: Next Action Date | K3: Status | L3: Days in Status | M3: Days to next
A4: =IF(tblOutreachLog_1[[#This Row],[Date]]<>0,ROW()-3,"") -> 1 | B4: 46096 | C4: Daya@taryag-group.com | D4: דיה לטוין | E4: תריג עיקור ומעבדות בעמ | F4: Email | G4: Schduale meeting with Alex & Yipaht | H4: Shir | I4: 46096 | J4: סטטוס | K4: Waiting of answer | L4: =TODAY()-tblOutreachLog_1[[#This Row],[Date]] -> 31 | M4: =tblOutreachLog_1[[#This Row],[Next Action]]-TODAY() -> -31
A5: =IF(tblOutreachLog_1[[#This Row],[Date]]<>0,ROW()-3,"") -> 2 | B5: 46096 | C5: uriel@norterra.co.il | D5: אוריאל פרמן | E5: נורטרה | F5: Email | G5: Schduale meeting with Alex & Yipaht | H5: Shir | I5: 46098 | J5: Meeting | K5: In Progress | L5: =TODAY()-tblOutreachLog_1[[#This Row],[Date]] -> 31 | M5: =tblOutreachLog_1[[#This Row],[Next Action]]-TODAY() -> -29
A6: =IF(tblOutreachLog_1[[#This Row],[Date]]<>0,ROW()-3,"") -> 3 | B6: 46096 | C6: maya@innoafrica.org | D6: מיה איל | E6: innovation Africa | F6: Email | G6: בקשה לפגישה עם יפעת | H6: Shir | I6: 46099 | J6: סטטוס | K6: Waiting of answer | L6: =TODAY()-tblOutreachLog_1[[#This Row],[Date]] -> 31 | M6: =tblOutreachLog_1[[#This Row],[Next Action]]-TODAY() -> -28
A7: =IF(tblOutreachLog_1[[#This Row],[Date]]<>0,ROW()-3,"") -> 4 | B7: 46096 | C7: nickyl@mor.org.il | D7: ניקי | E7: מור - מנכל מכון מור | F7: Email | G7: בקשה פגישה | H7: Shir | I7: 46099 | J7: סטטוס | K7: Waiting of answer | L7: =TODAY()-tblOutreachLog_1[[#This Row],[Date]] -> 31 | M7: =tblOutreachLog_1[[#This Row],[Next Action]]-TODAY() -> -28

Sheet Companies
A1: # | B1: Company Name | C1: Stage | D1: Source | E1: Website | F1: Type | G1: Track / Program | H1: Segment | I1: Notes | J1: Last Contact | K1: Interactions
A2: =IF(tblCompanies[[#This Row],[Company Name]]<>0,ROW()-1,"") -> 1 | B2: 3Dme | D2: Webinars 2.26 | E2: https://3dme.co.il | F2: Lead | I2: סריקות גוף והדפסת דמויות בתלת מימד | J2: =IFERROR(LOOKUP(2,1/('Outreach Log'!$E$2:$E$9998=B2),'Outreach Log'!$B$2:$B$9998),"") -> 46084 | K2: =COUNTIF('Outreach Log'!$E:$E,B2) -> 1
A3: =IF(tblCompanies[[#This Row],[Company Name]]<>0,ROW()-1,"") -> 2 | B3: Afimilk | D3: Webinars 2.26 | E3: https://afimilk.com | F3: Lead | I3: טכנולוגיות וניהול רפתות חלב | J3: =IFERROR(LOOKUP(2,1/('Outreach Log'!$E$2:$E$9998=B3),'Outreach Log'!$B$2:$B$9998),"") -> 46084 | K3: =COUNTIF('Outreach Log'!$E:$E,B3) -> 1
A4: =IF(tblCompanies[[#This Row],[Company Name]]<>0,ROW()-1,"") -> 3 | B4: Aigis Labs | D4: Webinars 2.26 | E4: https://aigis-labs.com | F4: Lead | I4: פתרונות לטיפול בפצעים ועור | J4: =IFERROR(LOOKUP(2,1/('Outreach Log'!$E$2:$E$9998=B4),'Outreach Log'!$B$2:$B$9998),"") -> 46084 | K4: =COUNTIF('Outreach Log'!$E:$E,B4) -> 1
A5: =IF(tblCompanies[[#This Row],[Company Name]]<>0,ROW()-1,"") -> 4 | B5: Ansora | D5: Webinars 2.26 | E5: https://www.ansora.ai/ | F5: Lead | I5: פלטפורמת תגמולים לקהילה ברשתות, מבוססת AI | J5: =IFERROR(LOOKUP(2,1/('Outreach Log'!$E$2:$E$9998=B5),'Outreach Log'!$B$2:$B$9998),"") -> 46084 | K5: =COUNTIF('Outreach Log'!$E:$E,B5) -> 1
A6: =IF(tblCompanies[[#This Row],[Company Name]]<>0,ROW()-1,"") -> 5 | B6: atlasensebiomed.com | D6: Webinars 2.26 | E6: https://atlasensebiomed.com | F6: Lead | I6: ניטור רפואי מרחוק וניתוח נתונים קליניים | J6: =IFERROR(LOOKUP(2,1/('Outreach Log'!$E$2:$E$9998=B6),'Outreach Log'!$B$2:$B$9998),"") -> 46084 | K6: =COUNTIF('Outreach Log'!$E:$E,B6) -> 1
A7: =IF(tblCompanies[[#This Row],[Company Name]]<>0,ROW()-1,"") -> 6 | B7: Attis Aviation | D7: Webinars 2.26 | E7: https://attis-aviation.com | F7: Lead | I7: פתרונות ותפעול כלי טיס בלתי מאוישים (UAS) | J7: =IFERROR(LOOKUP(2,1/('Outreach Log'!$E$2:$E$9998=B7),'Outreach Log'!$B$2:$B$9998),"") -> 46084 | K7: =COUNTIF('Outreach Log'!$E:$E,B7) -> 1
A8: =IF(tblCompanies[[#This Row],[Company Name]]<>0,ROW()-1,"") -> 7 | B8: Axioma | D8: Webinars 2.26 | E8: https://axioma-in.com | F8: Lead | I8: הנדסת מערכת ואינטגרציה לבטחון, HLS וערים חכמות | J8: =IFERROR(LOOKUP(2,1/('Outreach Log'!$E$2:$E$9998=B8),'Outreach Log'!$B$2:$B$9998),"") -> 46084 | K8: =COUNTIF('Outreach Log'!$E:$E,B8) -> 1
A9: =IF(tblCompanies[[#This Row],[Company Name]]<>0,ROW()-1,"") -> 8 | B9: BMC Helix | D9: Webinars 2.26 | E9: https://bmc.com | F9: Lead | I9: תוכנה לניהול IT ו-ITSM (BMC Helix) | J9: =IFERROR(LOOKUP(2,1/('Outreach Log'!$E$2:$E$9998=B9),'Outreach Log'!$B$2:$B$9998),"") -> 46084 | K9: =COUNTIF('Outreach Log'!$E:$E,B9) -> 1
A10: =IF(tblCompanies[[#This Row],[Company Name]]<>0,ROW()-1,"") -> 9 | B10: Bruker | D10: Webinars 2.26 | E10: https://bruker.com | F10: Lead | I10: מכשור מדעי ואנליטי למעבדות | J10: =IFERROR(LOOKUP(2,1/('Outreach Log'!$E$2:$E$9998=B10),'Outreach Log'!$B$2:$B$9998),"") -> 46084 | K10: =COUNTIF('Outreach Log'!$E:$E,B10) -> 1
A11: =IF(tblCompanies[[#This Row],[Company Name]]<>0,ROW()-1,"") -> 10 | B11: DenovAI | C11: Seed | D11: Webinars 2.26 | E11: https://denovai.com | F11: Lead | G11: הגברת השתתפות תאגידים תעשייתיים ישראליים בתכנית המסגרת האירופאית | I11: עיצוב חלבונים דה נובו באמצעות AI | J11: =IFERROR(LOOKUP(2,1/('Outreach Log'!$E$2:$E$9998=B11),'Outreach Log'!$B$2:$B$9998),"") -> 46084 | K11: =COUNTIF('Outreach Log'!$E:$E,B11) -> 1
A12: =IF(tblCompanies[[#This Row],[Company Name]]<>0,ROW()-1,"") -> 11 | B12: Desert Bird | C12: Pre Seed | D12: Webinars 2.26 | E12: https://desert-bird.com | F12: Lead | G12: תמיכה בביצוע פיילוטים (מסלול הטבה מס' 1) | I12: מערכות נגד רחפנים (Counter-UAS) | J12: =IFERROR(LOOKUP(2,1/('Outreach Log'!$E$2:$E$9998=B12),'Outreach Log'!$B$2:$B$9998),"") -> 46084 | K12: =COUNTIF('Outreach Log'!$E:$E,B12) -> 1
A13: =IF(tblCompanies[[#This Row],[Company Name]]<>0,ROW()-1,"") -> 12 | B13: Driveu.auto | D13: Webinars 2.26 | E13: https://driveu.auto | F13: Lead | I13: פלטפורמת קישוריות לטלה-אופרציה של רכבים אוטונומיים | J13: =IFERROR(LOOKUP(2,1/('Outreach Log'!$E$2:$E$9998=B13),'Outreach Log'!$B$2:$B$9998),"") -> 46084 | K13: =COUNTIF('Outreach Log'!$E:$E,B13) -> 1
A14: =IF(tblCompanies[[#This Row],[Company Name]]<>0,ROW()-1,"") -> 13 | B14: Emotion Logic | D14: Webinars 2.26 | E14: https://emotionlogic.ai | F14: Lead | I14: ניתוח רגשות בקול באמצעות AI | J14: =IFERROR(LOOKUP(2,1/('Outreach Log'!$E$2:$E$9998=B14),'Outreach Log'!$B$2:$B$9998),"") -> 46084 | K14: =COUNTIF('Outreach Log'!$E:$E,B14) -> 1
A15: =IF(tblCompanies[[#This Row],[Company Name]]<>0,ROW()-1,"") -> 14 | B15: ever after foods | D15: Webinars 2.26 | E15: https://everafterfoods.com | F15: Lead | I15: בשר מתורבת (cultivated meat) ופתרונות ייצור | J15: =IFERROR(LOOKUP(2,1/('Outreach Log'!$E$2:$E$9998=B15),'Outreach Log'!$B$2:$B$9998),"") -> 46084 | K15: =COUNTIF('Outreach Log'!$E:$E,B15) -> 1
A16: =IF(tblCompanies[[#This Row],[Company Name]]<>0,ROW()-1,"") -> 15 | B16: IEC | D16: Webinars 2.26 | E16: https://www.iec.co.il/ | F16: Lead | I16: חברת החשמל לישראל | J16: =IFERROR(LOOKUP(2,1/('Outreach Log'!$E$2:$E$9998=B16),'Outreach Log'!$B$2:$B$9998),"") -> 46084 | K16: =COUNTIF('Outreach Log'!$E:$E,B16) -> 1
A17: =IF(tblCompanies[[#This Row],[Company Name]]<>0,ROW()-1,"") -> 16 | B17: InFocus | D17: Webinars 2.26 | E17: https://www.infocus.com/ | F17: Lead | I17: ציוד תצוגה, מסכים ומקרנים | J17: =IFERROR(LOOKUP(2,1/('Outreach Log'!$E$2:$E$9998=B17),'Outreach Log'!$B$2:$B$9998),"") -> 46084 | K17: =COUNTIF('Outreach Log'!$E:$E,B17) -> 1
A18: =IF(tblCompanies[[#This Row],[Company Name]]<>0,ROW()-1,"") -> 17 | B18: Kokomodo | D18: Webinars 2.26 | E18: https://thekokomodo.com | F18: Lead | I18: nan | J18: =IFERROR(LOOKUP(2,1/('Outreach Log'!$E$2:$E$9998=B18),'Outreach Log'!$B$2:$B$9998),"") -> 46084 | K18: =COUNTIF('Outreach Log'!$E:$E,B18) -> 1
A19: =IF(tblCompanies[[#This Row],[Company Name]]<>0,ROW()-1,"") -> 18 | B19: NAVAIRO | D19: Webinars 2.26 | E19: https://navairo.com/ | F19: Lead | I19: פיוז׳ן חיישנים ל-UAV בעזרת AI | J19: =IFERROR(LOOKUP(2,1/('Outreach Log'!$E$2:$E$9998=B19),'Outreach Log'!$B$2:$B$9998),"") -> 46084 | K19: =COUNTIF('Outreach Log'!$E:$E,B19) -> 1
A20: =IF(tblCompanies[[#This Row],[Company Name]]<>0,ROW()-1,"") -> 19 | B20: Park Ariel Sharon | C20: Growth/Large Company | D20: Webinars 2.26 | E20: https://parksharon.co.il | F20: Lead | G20: הגברת השתתפות תאגידים תעשייתיים ישראליים בתכנית המסגרת האירופאית | I20: פארק שרון (מרכז עסקים/חדשנות) | J20: =IFERROR(LOOKUP(2,1/('Outreach Log'!$E$2:$E$9998=B20),'Outreach Log'!$B$2:$B$9998),"") -> 46084 | K20: =COUNTIF('Outreach Log'!$E:$E,B20) -> 1
A21: =IF(tblCompanies[[#This Row],[Company Name]]<>0,ROW()-1,"") -> 20 | B21: Pluri | D21: Webinars 2.26 | E21: https://mail.huji.ac.il | F21: Lead | I21: האוניברסיטה העברית | J21: =IFERROR(LOOKUP(2,1/('Outreach Log'!$E$2:$E$9998=B21),'Outreach Log'!$B$2:$B$9998),"") -> 46084 | K21: =COUNTIF('Outreach Log'!$E:$E,B21) -> 1
A22: =IF(tblCompanies[[#This Row],[Company Name]]<>0,ROW()-1,"") -> 21 | B22: qarakal | C22: Round A | D22: Webinars 2.26 | E22: https://qarakal.ai | F22: Lead | G22: קרן המו"פ – בקשת המשך שנה שניה/ שלישית לתאגיד צמיחה זכאי | I22: מחשוב קוונטי ומערכות היברידיות | J22: =IFERROR(LOOKUP(2,1/('Outreach Log'!$E$2:$E$9998=B22),'Outreach Log'!$B$2:$B$9998),"") -> 46084 | K22: =COUNTIF('Outreach Log'!$E:$E,B22) -> 1
A23: =IF(tblCompanies[[#This Row],[Company Name]]<>0,ROW()-1,"") -> 22 | B23: Wsc sports | D23: Webinars 2.26 | E23: https://wsc-sports.com/ | F23: Lead | I23: AI ליצירת תוכן ספורט מותאם אישית | J23: =IFERROR(LOOKUP(2,1/('Outreach Log'!$E$2:$E$9998=B23),'Outreach Log'!$B$2:$B$9998),"") -> 46084 | K23: =COUNTIF('Outreach Log'!$E:$E,B23) -> 1
A24: =IF(tblCompanies[[#This Row],[Company Name]]<>0,ROW()-1,"") -> 23 | B24: סופוויב | D24: Webinars 2.26 | E24: https://sofwave.com | F24: Lead | I24: טיפולי אולטרסאונד לא פולשניים לעור | J24: =IFERROR(LOOKUP(2,1/('Outreach Log'!$E$2:$E$9998=B24),'Outreach Log'!$B$2:$B$9998),"") -> 46084 | K24: =COUNTIF('Outreach Log'!$E:$E,B24) -> 1
A25: =IF(tblCompanies[[#This Row],[Company Name]]<>0,ROW()-1,"") -> 24 | B25: Beyon-D Innovations Ltd | D25: יפעת | E25: www.beyon-d.com | F25: Lead | H25: General Tech | I25: מיזם חדשנות טכנולוגי הפועל לפיתוח, האצה והבשלה של פתרונות חדשים. | J25: =IFERROR(LOOKUP(2,1/('Outreach Log'!$E$2:$E$9998=B25),'Outreach Log'!$B$2:$B$9998),"") | K25: =COUNTIF('Outreach Log'!$E:$E,B25) -> 0
A26: =IF(tblCompanies[[#This Row],[Company Name]]<>0,ROW()-1,"") -> 25 | B26: PolyX | D26: יפעת | E26: polyx.io | F26: Lead | H26: General Tech | I26: חברת טכנולוגיה הפועלת סביב פיתוח פתרונות חדשניים עם מיקוד במוצרים וחומרים מתקדמים. | J26: =IFERROR(LOOKUP(2,1/('Outreach Log'!$E$2:$E$9998=B26),'Outreach Log'!$B$2:$B$9998),"") | K26: =COUNTIF('Outreach Log'!$E:$E,B26) -> 0
A27: =IF(tblCompanies[[#This Row],[Company Name]]<>0,ROW()-1,"") -> 26 | B27: אדג' מדיקל ונצ'רס שותף כללי ,שותפות מוגבלת | D27: יפעת | E27: https://edgemed.vc | F27: Lead | G27: חממות טכנולוגיות לעידוד הקמה והשקעות הון לחברות הזנק | H27: General Tech | I27: אדג' מדיקל ונצ'רס היא קרן הון סיכון המתמקדת בטכנולוגיה רפואית, המפעילה חממה טכנולוגית ליצירה והשקעות הון בחברות הזנק | J27: =IFERROR(LOOKUP(2,1/('Outreach Log'!$E$2:$E$9998=B27),'Outreach Log'!$B$2:$B$9998),"") -> 46093 | K27: =COUNTIF('Outreach Log'!$E:$E,B27) -> 2
A28: =IF(tblCompanies[[#This Row],[Company Name]]<>0,ROW()-1,"") -> 27 | B28: אומניסול מערכות מידע בע"מ | D28: יפעת | E28: omnisol.co.il | F28: Lead | H28: AI, Software | I28: חברת תוכנה המפתחת מערכות ניהול מידע וידע מבוססות AI ואונטולוגיות. | J28: =IFERROR(LOOKUP(2,1/('Outreach Log'!$E$2:$E$9998=B28),'Outreach Log'!$B$2:$B$9998),"") -> 46093 | K28: =COUNTIF('Outreach Log'!$E:$E,B28) -> 4
A29: =IF(tblCompanies[[#This Row],[Company Name]]<>0,ROW()-1,"") -> 28 | B29: אוניברסיטת בן-גוריון B.G. Technologies & Application LTD Yazamut 360° | D29: יפעת | E29: https://www.bgu.ac.il/ | F29: Lead | H29: Academia | I29: יחידת המסחור והיזמות של אוניברסיטת בן-גוריון המחברת מחקר אקדמי לתעשייה ולסטארטאפים. | J29: =IFERROR(LOOKUP(2,1/('Outreach Log'!$E$2:$E$9998=B29),'Outreach Log'!$B$2:$B$9998),"") -> 46093 | K29: =COUNTIF('Outreach Log'!$E:$E,B29) -> 1
A30: =IF(tblCompanies[[#This Row],[Company Name]]<>0,ROW()-1,"") -> 29 | B30: אוניברסיטת חיפה | C30: Startups Creation Platforms | D30: רשהח"ד 2025 | E30: https://haifa.ac.il | F30: Lead | G30: קרן ההון האנושי להייטק | H30: Academia | I30: אוניברסיטת מחקר המציעה מסלולי הכשרה לפיתוח ועידוד יזמות באמצעות המרכז ליזמות וחדשנות ורשת השותפויות הבין מגזריות שהוא יוצר | J30: =IFERROR(LOOKUP(2,1/('Outreach Log'!$E$2:$E$9998=B30),'Outreach Log'!$B$2:$B$9998),"") -> 46126 | K30: =COUNTIF('Outreach Log'!$E:$E,B30) -> 3
A31: =IF(tblCompanies[[#This Row],[Company Name]]<>0,ROW()-1,"") -> 30 | B31: אי אייץ' וי ישראל, שותפות מוגבלת | D31: יפעת | E31: http://www.ehealthventures.com | F31: Lead | H31: Medical device | I31: קרן הון סיכון בתחום הבריאות הדיגיטלית והמדטק המשקיעה בשלבים מוקדמים. | J31: =IFERROR(LOOKUP(2,1/('Outreach Log'!$E$2:$E$9998=B31),'Outreach Log'!$B$2:$B$9998),"") -> 46093 | K31: =COUNTIF('Outreach Log'!$E:$E,B31) -> 3
A32: =IF(tblCompanies[[#This Row],[Company Name]]<>0,ROW()-1,"") -> 31 | B32: אי. אי. ג'י-סנס בע"מ | D32: יפעת | E32: http://www.brain.space | F32: Lead | G32: מסלול מעבדות מו״פ ומאגרי מידע- קרן תשתיות המו"פ | H32: Medical device, AI | I32: Brain.space מפתחת בינה מלאכותית מבוססת מודלים מנטליים ודאטה מוחית, לחיזוי התנהגויות ופרסונליזציה של מוצרים ושירותים. זאת באמצעות פלטפורמת Brain-Data-as-a-Service לאיסוף וניתוח דאטה מוחי. | J32: =IFERROR(LOOKUP(2,1/('Outreach Log'!$E$2:$E$9998=B32),'Outreach Log'!$B$2:$B$9998),"") -> 46093 | K32: =COUNTIF('Outreach Log'!$E:$E,B32) -> 3
A33: =IF(tblCompanies[[#This Row],[Company Name]]<>0,ROW()-1,"") -> 32 | B33: איגנייט דיפטק בע״מ | D33: יפעת | E33: http://www.ignitedeeptech.com | F33: Lead | G33: קרן ההון האנושי להייטק | H33: General Tech | I33: איגנייט תאגיד להאצת חברות הזנק | J33: =IFERROR(LOOKUP(2,1/('Outreach Log'!$E$2:$E$9998=B33),'Outreach Log'!$B$2:$B$9998),"") -> 46093 | K33: =COUNTIF('Outreach Log'!$E:$E,B33) -> 2
A34: =IF(tblCompanies[[#This Row],[Company Name]]<>0,ROW()-1,"") -> 33 | B34: איון לאבס מעבדת חדשנות בע"מ | C34: Startups Creation Platforms | D34: רשהח"ד 2025 | E34: https://aionlabs.com | F34: Lead | G34: מעבדות לחדשנות טכנולוגית - תפעול שוטף/ תשתית טכנולוגית | H34: AI | I34: מעבדה לחדשנות | J34: =IFERROR(LOOKUP(2,1/('Outreach Log'!$E$2:$E$9998=B34),'Outreach Log'!$B$2:$B$9998),"") -> 46093 | K34: =COUNTIF('Outreach Log'!$E:$E,B34) -> 3
A35: =IF(tblCompanies[[#This Row],[Company Name]]<>0,ROW()-1,"") -> 34 | B35: אינוביסטק | D35: יפעת | E35: https://innoveast.org | F35: Lead | G35: מסגרות האצת חדשנות- מרכזי חדשנות טכנולוגית | H35: Academia | I35: המרכז מקדם יזמות, תעסוקה וחדשנות בהייטק באזור יהודה ושומרון באמצעות שותפויות אסטרטגיות, הכשרות מקצועיות, תמיכה במיזמים ויצירת קהילה יזמית מחוברת ומעצימה. | J35: =IFERROR(LOOKUP(2,1/('Outreach Log'!$E$2:$E$9998=B35),'Outreach Log'!$B$2:$B$9998),"") -> 46126 | K35: =COUNTIF('Outreach Log'!$E:$E,B35) -> 2
A36: =IF(tblCompanies[[#This Row],[Company Name]]<>0,ROW()-1,"") -> 35 | B36: אלאג'ן בע"מ | D36: יפעת | E36: http://www.alagene.co.il | F36: Lead | G36: מסלול מאגדי מחקר יישומי- קרן המחקר היישומי | H36: Biology | I36: אלאג'ין הינה חברת שירותים בביולוגיה סינתטית המאפשרת לחוקרים, חברות ויזמים לקדם חדשנות טכנולוגית החל משלבי מחקר ופיתוח ועד גמלון ומסחור של ביו-תהליכים. החברה מתמחה בהנדסת זנים, פרמנטציה ותהליכי ניקוי חלבונים לשיפור ייצור מיקרוביאלי יעיל ובר-קיימא | J36: =IFERROR(LOOKUP(2,1/('Outreach Log'!$E$2:$E$9998=B36),'Outreach Log'!$B$2:$B$9998),"") -> 46093 | K36: =COUNTIF('Outreach Log'!$E:$E,B36) -> 2
A37: =IF(tblCompanies[[#This Row],[Company Name]]<>0,ROW()-1,"") -> 36 | B37: אלון מדטק ונצ'רס בע"מ | D37: יפעת | E37: http://www.alon-medtech.com/ | F37: Lead | H37: Medical device | I37: חממת מדטק המשקיעה ומלווה מיזמים בשלבים מוקדמים בתחום המכשור הרפואי. | J37: =IFERROR(LOOKUP(2,1/('Outreach Log'!$E$2:$E$9998=B37),'Outreach Log'!$B$2:$B$9998),"") -> 46093 | K37: =COUNTIF('Outreach Log'!$E:$E,B37) -> 4
A38: =IF(tblCompanies[[#This Row],[Company Name]]<>0,ROW()-1,"") -> 37 | B38: אפקה המכללה האקדמית להנדסה בת"א | D38: יפעת | E38: https://afeka.ac.il | F38: Lead | G38: מסלול מאגדי מחקר יישומי- קרן המחקר היישומי | H38: Academia | I38: אפקה המכללה להנדסה בתל אביב | J38: =IFERROR(LOOKUP(2,1/('Outreach Log'!$E$2:$E$9998=B38),'Outreach Log'!$B$2:$B$9998),"") -> 46126 | K38: =COUNTIF('Outreach Log'!$E:$E,B38) -> 3
A39: =IF(tblCompanies[[#This Row],[Company Name]]<>0,ROW()-1,"") -> 38 | B39: ארבה רובוטיקס בע"מ | D39: יפעת | E39: http://www.arberobotics.com/ | F39: Lead | H39: Robotics | I39: מפתחת רדאר הדמייתי 4D לרכב אוטונומי ומערכות סיוע לנהג. | J39: =IFERROR(LOOKUP(2,1/('Outreach Log'!$E$2:$E$9998=B39),'Outreach Log'!$B$2:$B$9998),"") -> 46093 | K39: =COUNTIF('Outreach Log'!$E:$E,B39) -> 3
A40: =IF(tblCompanies[[#This Row],[Company Name]]<>0,ROW()-1,"") -> 39 | B40: ארט מדיקל בע"מ | D40: יפעת | E40: https://artmedical.com/ | F40: Lead | G40: הגברת השתתפות תאגידים תעשייתיים ישראליים בתכנית המסגרת האירופאית | H40: General Tech | I40: ארט מדיקל בע"מ | J40: =IFERROR(LOOKUP(2,1/('Outreach Log'!$E$2:$E$9998=B40),'Outreach Log'!$B$2:$B$9998),"") -> 46093 | K40: =COUNTIF('Outreach Log'!$E:$E,B40) -> 4
...

Sheet Contacts
A1: # | B1: First Name | C1: Last Name | D1: Title / Role | E1: Company | F1: Email | G1: Phone | H1: Type | I1: Source | J1: Notes | K1: Last Interaction | L1: Last Type | M1: → Interaction | N1: → Company
A2: =IF(tblContacts[[#This Row],[First Name]]<>0,ROW()-1,"") -> 1 | B2: אדם | C2: לב | E2: מקורות | F2: 1adamleb@gmail.com | H2: Lead | I2: Webinars 2.26 | K2: {=IFERROR(LOOKUP(2,1/('Outreach Log'!$C$2:$C$9998=F2),'Outreach Log'!$B$2:$B$9998),"")} -> 46126 | L2: =IFERROR(INDEX('Outreach Log'!$F:$F,MATCH(TEXT(K2,"YYYY-MM-DD")&F2,'Outreach Log'!$L:$L,0)),"") -> Email | M2: =IFERROR(HYPERLINK("#'Outreach Log'!A"&MATCH(TEXT(K2,"YYYY-MM-DD")&F2,'Outreach Log'!$L:$L,0),"→ View"),"—") -> → View | N2: =IFERROR(HYPERLINK("#Companies!A"&MATCH(E2,Companies!$B:$B,0),"→ View"),"—") -> → View
A3: =IF(tblContacts[[#This Row],[First Name]]<>0,ROW()-1,"") -> 2 | B3: עדי | C3: גולדמן | E3: ביוטיק סירקולר טכנולוגיות בע"מ | F3: adi@biotic-labs.com | H3: Lead | I3: רשהח"ד 2025 | K3: {=IFERROR(LOOKUP(2,1/('Outreach Log'!$C$2:$C$9998=F3),'Outreach Log'!$B$2:$B$9998),"")} | L3: =IFERROR(INDEX('Outreach Log'!$F:$F,MATCH(TEXT(K3,"YYYY-MM-DD")&F3,'Outreach Log'!$L:$L,0)),"") | M3: =IFERROR(HYPERLINK("#'Outreach Log'!A"&MATCH(TEXT(K3,"YYYY-MM-DD")&F3,'Outreach Log'!$L:$L,0),"→ View"),"—") -> — | N3: =IFERROR(HYPERLINK("#Companies!A"&MATCH(E3,Companies!$B:$B,0),"→ View"),"—") -> → View
A4: =IF(tblContacts[[#This Row],[First Name]]<>0,ROW()-1,"") -> 3 | B4: עדי | C4: פנחס | E4: קלארו איי איי בע"מ | F4: adi@claroai.com | H4: Lead | I4: רשהח"ד 2025 | K4: {=IFERROR(LOOKUP(2,1/('Outreach Log'!$C$2:$C$9998=F4),'Outreach Log'!$B$2:$B$9998),"")} | L4: =IFERROR(INDEX('Outreach Log'!$F:$F,MATCH(TEXT(K4,"YYYY-MM-DD")&F4,'Outreach Log'!$L:$L,0)),"") | M4: =IFERROR(HYPERLINK("#'Outreach Log'!A"&MATCH(TEXT(K4,"YYYY-MM-DD")&F4,'Outreach Log'!$L:$L,0),"→ View"),"—") -> — | N4: =IFERROR(HYPERLINK("#Companies!A"&MATCH(E4,Companies!$B:$B,0),"→ View"),"—") -> → View
A5: =IF(tblContacts[[#This Row],[First Name]]<>0,ROW()-1,"") -> 4 | B5: עדי | C5: כוסטה | E5: קופיילוט אמ.די בע"מ | F5: adi@copilotmd.ai | H5: Lead | I5: רשהח"ד 2025 | K5: {=IFERROR(LOOKUP(2,1/('Outreach Log'!$C$2:$C$9998=F5),'Outreach Log'!$B$2:$B$9998),"")} -> 46126 | L5: =IFERROR(INDEX('Outreach Log'!$F:$F,MATCH(TEXT(K5,"YYYY-MM-DD")&F5,'Outreach Log'!$L:$L,0)),"") -> Email | M5: =IFERROR(HYPERLINK("#'Outreach Log'!A"&MATCH(TEXT(K5,"YYYY-MM-DD")&F5,'Outreach Log'!$L:$L,0),"→ View"),"—") -> → View | N5: =IFERROR(HYPERLINK("#Companies!A"&MATCH(E5,Companies!$B:$B,0),"→ View"),"—") -> → View
A6: =IF(tblContacts[[#This Row],[First Name]]<>0,ROW()-1,"") -> 5 | B6: עדי | C6: זייפרט | E6: למו טק בע"מ | F6: adi@drinklamu.com | H6: Lead | I6: רשהח"ד 2025 | K6: {=IFERROR(LOOKUP(2,1/('Outreach Log'!$C$2:$C$9998=F6),'Outreach Log'!$B$2:$B$9998),"")} | L6: =IFERROR(INDEX('Outreach Log'!$F:$F,MATCH(TEXT(K6,"YYYY-MM-DD")&F6,'Outreach Log'!$L:$L,0)),"") | M6: =IFERROR(HYPERLINK("#'Outreach Log'!A"&MATCH(TEXT(K6,"YYYY-MM-DD")&F6,'Outreach Log'!$L:$L,0),"→ View"),"—") -> — | N6: =IFERROR(HYPERLINK("#Companies!A"&MATCH(E6,Companies!$B:$B,0),"→ View"),"—") -> → View
A7: =IF(tblContacts[[#This Row],[First Name]]<>0,ROW()-1,"") -> 6 | B7: עדי | C7: נתן | E7: מושן אנליטיקס בע"מ | F7: adi@motionanalytics.io | H7: Lead | I7: רשהח"ד 2025 | K7: {=IFERROR(LOOKUP(2,1/('Outreach Log'!$C$2:$C$9998=F7),'Outreach Log'!$B$2:$B$9998),"")} -> 46126 | L7: =IFERROR(INDEX('Outreach Log'!$F:$F,MATCH(TEXT(K7,"YYYY-MM-DD")&F7,'Outreach Log'!$L:$L,0)),"") -> Email | M7: =IFERROR(HYPERLINK("#'Outreach Log'!A"&MATCH(TEXT(K7,"YYYY-MM-DD")&F7,'Outreach Log'!$L:$L,0),"→ View"),"—") -> → View | N7: =IFERROR(HYPERLINK("#Companies!A"&MATCH(E7,Companies!$B:$B,0),"→ View"),"—") -> → View
A8: =IF(tblContacts[[#This Row],[First Name]]<>0,ROW()-1,"") -> 7 | B8: עדי | C8: שלו | D8: COO | E8: Noyad | F8: adi@noyad.co.il | H8: Lead | I8: Webinars 2.26 | K8: {=IFERROR(LOOKUP(2,1/('Outreach Log'!$C$2:$C$9998=F8),'Outreach Log'!$B$2:$B$9998),"")} | L8: =IFERROR(INDEX('Outreach Log'!$F:$F,MATCH(TEXT(K8,"YYYY-MM-DD")&F8,'Outreach Log'!$L:$L,0)),"") | M8: =IFERROR(HYPERLINK("#'Outreach Log'!A"&MATCH(TEXT(K8,"YYYY-MM-DD")&F8,'Outreach Log'!$L:$L,0),"→ View"),"—") -> — | N8: =IFERROR(HYPERLINK("#Companies!A"&MATCH(E8,Companies!$B:$B,0),"→ View"),"—") -> → View
A9: =IF(tblContacts[[#This Row],[First Name]]<>0,ROW()-1,"") -> 8 | B9: אהדאב | C9: סרחאן | E9: ג'ין סטייל א.איי בע"מ | F9: ahdab@vstylr.ai | H9: Lead | I9: רשהח"ד 2025 | K9: {=IFERROR(LOOKUP(2,1/('Outreach Log'!$C$2:$C$9998=F9),'Outreach Log'!$B$2:$B$9998),"")} | L9: =IFERROR(INDEX('Outreach Log'!$F:$F,MATCH(TEXT(K9,"YYYY-MM-DD")&F9,'Outreach Log'!$L:$L,0)),"") | M9: =IFERROR(HYPERLINK("#'Outreach Log'!A"&MATCH(TEXT(K9,"YYYY-MM-DD")&F9,'Outreach Log'!$L:$L,0),"→ View"),"—") -> — | N9: =IFERROR(HYPERLINK("#Companies!A"&MATCH(E9,Companies!$B:$B,0),"→ View"),"—") -> → View
A10: =IF(tblContacts[[#This Row],[First Name]]<>0,ROW()-1,"") -> 9 | B10: עמיחי | C10: חיים גרוס | E10: Marine Edge | F10: ahg@marine-edge.com | H10: Lead | I10: רשהח"ד 2025 | K10: {=IFERROR(LOOKUP(2,1/('Outreach Log'!$C$2:$C$9998=F10),'Outreach Log'!$B$2:$B$9998),"")} -> 46126 | L10: =IFERROR(INDEX('Outreach Log'!$F:$F,MATCH(TEXT(K10,"YYYY-MM-DD")&F10,'Outreach Log'!$L:$L,0)),"") -> Email | M10: =IFERROR(HYPERLINK("#'Outreach Log'!A"&MATCH(TEXT(K10,"YYYY-MM-DD")&F10,'Outreach Log'!$L:$L,0),"→ View"),"—") -> → View | N10: =IFERROR(HYPERLINK("#Companies!A"&MATCH(E10,Companies!$B:$B,0),"→ View"),"—") -> → View
A11: =IF(tblContacts[[#This Row],[First Name]]<>0,ROW()-1,"") -> 10 | B11: אימן | C11: סיף | E11: מרכז החדשנות נורת' מד בע"מ | F11: aiman.saif@portlandtrust.org.il | H11: Lead | I11: רשהח"ד 2025 | K11: {=IFERROR(LOOKUP(2,1/('Outreach Log'!$C$2:$C$9998=F11),'Outreach Log'!$B$2:$B$9998),"")} -> 46126 | L11: =IFERROR(INDEX('Outreach Log'!$F:$F,MATCH(TEXT(K11,"YYYY-MM-DD")&F11,'Outreach Log'!$L:$L,0)),"") -> Email | M11: =IFERROR(HYPERLINK("#'Outreach Log'!A"&MATCH(TEXT(K11,"YYYY-MM-DD")&F11,'Outreach Log'!$L:$L,0),"→ View"),"—") -> → View | N11: =IFERROR(HYPERLINK("#Companies!A"&MATCH(E11,Companies!$B:$B,0),"→ View"),"—") -> → View
A12: =IF(tblContacts[[#This Row],[First Name]]<>0,ROW()-1,"") -> 11 | B12: אלכסיי | C12: דומשלק | E12: טרטדש בע"ם Threatdash LTD | F12: alex.domshlak@threatdash.com | H12: Lead | I12: רשהח"ד 2025 | K12: {=IFERROR(LOOKUP(2,1/('Outreach Log'!$C$2:$C$9998=F12),'Outreach Log'!$B$2:$B$9998),"")} | L12: =IFERROR(INDEX('Outreach Log'!$F:$F,MATCH(TEXT(K12,"YYYY-MM-DD")&F12,'Outreach Log'!$L:$L,0)),"") | M12: =IFERROR(HYPERLINK("#'Outreach Log'!A"&MATCH(TEXT(K12,"YYYY-MM-DD")&F12,'Outreach Log'!$L:$L,0),"→ View"),"—") -> — | N12: =IFERROR(HYPERLINK("#Companies!A"&MATCH(E12,Companies!$B:$B,0),"→ View"),"—") -> → View
A13: =IF(tblContacts[[#This Row],[First Name]]<>0,ROW()-1,"") -> 12 | B13: אלכסנדר | C13: וקסלר | E13: גרינגיין אנרג'י בע"מ | F13: alexveksler19@gmail.com | H13: Lead | I13: רשהח"ד 2025 | K13: {=IFERROR(LOOKUP(2,1/('Outreach Log'!$C$2:$C$9998=F13),'Outreach Log'!$B$2:$B$9998),"")} -> 46126 | L13: =IFERROR(INDEX('Outreach Log'!$F:$F,MATCH(TEXT(K13,"YYYY-MM-DD")&F13,'Outreach Log'!$L:$L,0)),"") -> Email | M13: =IFERROR(HYPERLINK("#'Outreach Log'!A"&MATCH(TEXT(K13,"YYYY-MM-DD")&F13,'Outreach Log'!$L:$L,0),"→ View"),"—") -> → View | N13: =IFERROR(HYPERLINK("#Companies!A"&MATCH(E13,Companies!$B:$B,0),"→ View"),"—") -> → View
A14: =IF(tblContacts[[#This Row],[First Name]]<>0,ROW()-1,"") -> 13 | B14: אלון | C14: מעוז | D14: CEO | E14: Twine | F14: allon.maoz27@gmail.com | H14: Lead | I14: Webinars 2.26 | K14: {=IFERROR(LOOKUP(2,1/('Outreach Log'!$C$2:$C$9998=F14),'Outreach Log'!$B$2:$B$9998),"")} | L14: =IFERROR(INDEX('Outreach Log'!$F:$F,MATCH(TEXT(K14,"YYYY-MM-DD")&F14,'Outreach Log'!$L:$L,0)),"") | M14: =IFERROR(HYPERLINK("#'Outreach Log'!A"&MATCH(TEXT(K14,"YYYY-MM-DD")&F14,'Outreach Log'!$L:$L,0),"→ View"),"—") -> — | N14: =IFERROR(HYPERLINK("#Companies!A"&MATCH(E14,Companies!$B:$B,0),"→ View"),"—") -> → View
A15: =IF(tblContacts[[#This Row],[First Name]]<>0,ROW()-1,"") -> 14 | B15: אלון | C15: מעוז | E15: טווין פתרונות בע"מ | F15: allon@twine-s.com | H15: Lead | I15: רשהח"ד 2025 | K15: {=IFERROR(LOOKUP(2,1/('Outreach Log'!$C$2:$C$9998=F15),'Outreach Log'!$B$2:$B$9998),"")} | L15: =IFERROR(INDEX('Outreach Log'!$F:$F,MATCH(TEXT(K15,"YYYY-MM-DD")&F15,'Outreach Log'!$L:$L,0)),"") | M15: =IFERROR(HYPERLINK("#'Outreach Log'!A"&MATCH(TEXT(K15,"YYYY-MM-DD")&F15,'Outreach Log'!$L:$L,0),"→ View"),"—") -> — | N15: =IFERROR(HYPERLINK("#Companies!A"&MATCH(E15,Companies!$B:$B,0),"→ View"),"—") -> → View
A16: =IF(tblContacts[[#This Row],[First Name]]<>0,ROW()-1,"") -> 15 | B16: אלון | C16: ניצן | E16: ה.י. ניאו-ריי לאבס בע"מ | F16: alon@neuray.ai | H16: Lead | I16: רשהח"ד 2025 | K16: {=IFERROR(LOOKUP(2,1/('Outreach Log'!$C$2:$C$9998=F16),'Outreach Log'!$B$2:$B$9998),"")} -> 46126 | L16: =IFERROR(INDEX('Outreach Log'!$F:$F,MATCH(TEXT(K16,"YYYY-MM-DD")&F16,'Outreach Log'!$L:$L,0)),"") -> Email | M16: =IFERROR(HYPERLINK("#'Outreach Log'!A"&MATCH(TEXT(K16,"YYYY-MM-DD")&F16,'Outreach Log'!$L:$L,0),"→ View"),"—") -> → View | N16: =IFERROR(HYPERLINK("#Companies!A"&MATCH(E16,Companies!$B:$B,0),"→ View"),"—") -> → View
A17: =IF(tblContacts[[#This Row],[First Name]]<>0,ROW()-1,"") -> 16 | B17: אלון | C17: כהן | E17: קוואמקור בע"מ | F17: alon@quamcore.com | H17: Lead | I17: רשהח"ד 2025 | K17: {=IFERROR(LOOKUP(2,1/('Outreach Log'!$C$2:$C$9998=F17),'Outreach Log'!$B$2:$B$9998),"")} | L17: =IFERROR(INDEX('Outreach Log'!$F:$F,MATCH(TEXT(K17,"YYYY-MM-DD")&F17,'Outreach Log'!$L:$L,0)),"") | M17: =IFERROR(HYPERLINK("#'Outreach Log'!A"&MATCH(TEXT(K17,"YYYY-MM-DD")&F17,'Outreach Log'!$L:$L,0),"→ View"),"—") -> — | N17: =IFERROR(HYPERLINK("#Companies!A"&MATCH(E17,Companies!$B:$B,0),"→ View"),"—") -> → View
A18: =IF(tblContacts[[#This Row],[First Name]]<>0,ROW()-1,"") -> 17 | B18: אלון | C18: מטריקין | E18: סקינקובטור נאוקר | F18: alon@skincubator-neocare.com | H18: Lead | I18: רשהח"ד 2025 | K18: {=IFERROR(LOOKUP(2,1/('Outreach Log'!$C$2:$C$9998=F18),'Outreach Log'!$B$2:$B$9998),"")} | L18: =IFERROR(INDEX('Outreach Log'!$F:$F,MATCH(TEXT(K18,"YYYY-MM-DD")&F18,'Outreach Log'!$L:$L,0)),"") | M18: =IFERROR(HYPERLINK("#'Outreach Log'!A"&MATCH(TEXT(K18,"YYYY-MM-DD")&F18,'Outreach Log'!$L:$L,0),"→ View"),"—") -> — | N18: =IFERROR(HYPERLINK("#Companies!A"&MATCH(E18,Companies!$B:$B,0),"→ View"),"—") -> → View
A19: =IF(tblContacts[[#This Row],[First Name]]<>0,ROW()-1,"") -> 18 | B19: אמיר | C19: הורוביץ | E19: אי אס איי אל טכנולוגיות, שותפות מוגבלת | F19: amir.h@esil.co.il | H19: Lead | I19: רשהח"ד 2025 | K19: {=IFERROR(LOOKUP(2,1/('Outreach Log'!$C$2:$C$9998=F19),'Outreach Log'!$B$2:$B$9998),"")} -> 46126 | L19: =IFERROR(INDEX('Outreach Log'!$F:$F,MATCH(TEXT(K19,"YYYY-MM-DD")&F19,'Outreach Log'!$L:$L,0)),"") -> Email | M19: =IFERROR(HYPERLINK("#'Outreach Log'!A"&MATCH(TEXT(K19,"YYYY-MM-DD")&F19,'Outreach Log'!$L:$L,0),"→ View"),"—") -> → View | N19: =IFERROR(HYPERLINK("#Companies!A"&MATCH(E19,Companies!$B:$B,0),"→ View"),"—") -> → View
A20: =IF(tblContacts[[#This Row],[First Name]]<>0,ROW()-1,"") -> 19 | B20: אמיר | C20: רייכמן | E20: סאינאי אימונותרפאוטיקה בע"מ | F20: amir.reichman@scinai.com | H20: Lead | I20: רשהח"ד 2025 | K20: {=IFERROR(LOOKUP(2,1/('Outreach Log'!$C$2:$C$9998=F20),'Outreach Log'!$B$2:$B$9998),"")} | L20: =IFERROR(INDEX('Outreach Log'!$F:$F,MATCH(TEXT(K20,"YYYY-MM-DD")&F20,'Outreach Log'!$L:$L,0)),"") | M20: =IFERROR(HYPERLINK("#'Outreach Log'!A"&MATCH(TEXT(K20,"YYYY-MM-DD")&F20,'Outreach Log'!$L:$L,0),"→ View"),"—") -> — | N20: =IFERROR(HYPERLINK("#Companies!A"&MATCH(E20,Companies!$B:$B,0),"→ View"),"—") -> → View
A21: =IF(tblContacts[[#This Row],[First Name]]<>0,ROW()-1,"") -> 20 | B21: אמיר | C21: שדה | E21: טראומה סינק בע"מ | F21: amir.sadeh@gmail.com | H21: Lead | I21: רשהח"ד 2025 | K21: {=IFERROR(LOOKUP(2,1/('Outreach Log'!$C$2:$C$9998=F21),'Outreach Log'!$B$2:$B$9998),"")} -> 46126 | L21: =IFERROR(INDEX('Outreach Log'!$F:$F,MATCH(TEXT(K21,"YYYY-MM-DD")&F21,'Outreach Log'!$L:$L,0)),"") -> Email | M21: =IFERROR(HYPERLINK("#'Outreach Log'!A"&MATCH(TEXT(K21,"YYYY-MM-DD")&F21,'Outreach Log'!$L:$L,0),"→ View"),"—") -> → View | N21: =IFERROR(HYPERLINK("#Companies!A"&MATCH(E21,Companies!$B:$B,0),"→ View"),"—") -> → View
A22: =IF(tblContacts[[#This Row],[First Name]]<>0,ROW()-1,"") -> 21 | B22: אמיר | C22: חסידים | E22: אייפקס ביו בע"מ | F22: amir@apexbio.tech | H22: Lead | I22: רשהח"ד 2025 | K22: {=IFERROR(LOOKUP(2,1/('Outreach Log'!$C$2:$C$9998=F22),'Outreach Log'!$B$2:$B$9998),"")} -> 46126 | L22: =IFERROR(INDEX('Outreach Log'!$F:$F,MATCH(TEXT(K22,"YYYY-MM-DD")&F22,'Outreach Log'!$L:$L,0)),"") -> Email | M22: =IFERROR(HYPERLINK("#'Outreach Log'!A"&MATCH(TEXT(K22,"YYYY-MM-DD")&F22,'Outreach Log'!$L:$L,0),"→ View"),"—") -> → View | N22: =IFERROR(HYPERLINK("#Companies!A"&MATCH(E22,Companies!$B:$B,0),"→ View"),"—") -> → View
A23: =IF(tblContacts[[#This Row],[First Name]]<>0,ROW()-1,"") -> 22 | B23: אמיר | C23: ממט | D23: VP Product/R&D | E23: אקסיומה רובוטיקס בע"מ | F23: amir@axioma-in.com | H23: Lead | I23: רשהח"ד 2025 | K23: {=IFERROR(LOOKUP(2,1/('Outreach Log'!$C$2:$C$9998=F23),'Outreach Log'!$B$2:$B$9998),"")} -> 46126 | L23: =IFERROR(INDEX('Outreach Log'!$F:$F,MATCH(TEXT(K23,"YYYY-MM-DD")&F23,'Outreach Log'!$L:$L,0)),"") -> Email | M23: =IFERROR(HYPERLINK("#'Outreach Log'!A"&MATCH(TEXT(K23,"YYYY-MM-DD")&F23,'Outreach Log'!$L:$L,0),"→ View"),"—") -> → View | N23: =IFERROR(HYPERLINK("#Companies!A"&MATCH(E23,Companies!$B:$B,0),"→ View"),"—") -> → View
A24: =IF(tblContacts[[#This Row],[First Name]]<>0,ROW()-1,"") -> 23 | B24: אמיר | C24: לויט | E24: רמוט אנרג'י בע"מ | F24: amir@remot.energy | H24: Lead | I24: רשהח"ד 2025 | K24: {=IFERROR(LOOKUP(2,1/('Outreach Log'!$C$2:$C$9998=F24),'Outreach Log'!$B$2:$B$9998),"")} -> 46126 | L24: =IFERROR(INDEX('Outreach Log'!$F:$F,MATCH(TEXT(K24,"YYYY-MM-DD")&F24,'Outreach Log'!$L:$L,0)),"") -> Email | M24: =IFERROR(HYPERLINK("#'Outreach Log'!A"&MATCH(TEXT(K24,"YYYY-MM-DD")&F24,'Outreach Log'!$L:$L,0),"→ View"),"—") -> → View | N24: =IFERROR(HYPERLINK("#Companies!A"&MATCH(E24,Companies!$B:$B,0),"→ View"),"—") -> → View
A25: =IF(tblContacts[[#This Row],[First Name]]<>0,ROW()-1,"") -> 24 | B25: עמית | C25: טורמן | E25: ויריטיס בע"מ | F25: amit.turman@viritis2020.com | H25: Lead | I25: רשהח"ד 2025 | K25: {=IFERROR(LOOKUP(2,1/('Outreach Log'!$C$2:$C$9998=F25),'Outreach Log'!$B$2:$B$9998),"")} -> 46126 | L25: =IFERROR(INDEX('Outreach Log'!$F:$F,MATCH(TEXT(K25,"YYYY-MM-DD")&F25,'Outreach Log'!$L:$L,0)),"") -> Email | M25: =IFERROR(HYPERLINK("#'Outreach Log'!A"&MATCH(TEXT(K25,"YYYY-MM-DD")&F25,'Outreach Log'!$L:$L,0),"→ View"),"—") -> → View | N25: =IFERROR(HYPERLINK("#Companies!A"&MATCH(E25,Companies!$B:$B,0),"→ View"),"—") -> → View
A26: =IF(tblContacts[[#This Row],[First Name]]<>0,ROW()-1,"") -> 25 | B26: עמית | C26: מלר | D26: Co-Founder & CSO | E26: ג'נופור | G26: 0545667676 | H26: Lead | I26: רשהח"ד 2026 | K26: {=IFERROR(LOOKUP(2,1/('Outreach Log'!$C$2:$C$9998=F26),'Outreach Log'!$B$2:$B$9998),"")} -> 0 | L26: =IFERROR(INDEX('Outreach Log'!$F:$F,MATCH(TEXT(K26,"YYYY-MM-DD")&F26,'Outreach Log'!$L:$L,0)),"") | M26: =IFERROR(HYPERLINK("#'Outreach Log'!A"&MATCH(TEXT(K26,"YYYY-MM-DD")&F26,'Outreach Log'!$L:$L,0),"→ View"),"—") -> — | N26: =IFERROR(HYPERLINK("#Companies!A"&MATCH(E26,Companies!$B:$B,0),"→ View"),"—") -> → View
A27: =IF(tblContacts[[#This Row],[First Name]]<>0,ROW()-1,"") -> 26 | B27: עמית | C27: קריג | D27: SVP Software & Product Line | E27: מלאנוקס טכנולוגיות | F27: amit@mellanox.com | H27: Lead | I27: רשהח"ד 2026 | K27: {=IFERROR(LOOKUP(2,1/('Outreach Log'!$C$2:$C$9998=F27),'Outreach Log'!$B$2:$B$9998),"")} | L27: =IFERROR(INDEX('Outreach Log'!$F:$F,MATCH(TEXT(K27,"YYYY-MM-DD")&F27,'Outreach Log'!$L:$L,0)),"") | M27: =IFERROR(HYPERLINK("#'Outreach Log'!A"&MATCH(TEXT(K27,"YYYY-MM-DD")&F27,'Outreach Log'!$L:$L,0),"→ View"),"—") -> — | N27: =IFERROR(HYPERLINK("#Companies!A"&MATCH(E27,Companies!$B:$B,0),"→ View"),"—") -> → View
A28: =IF(tblContacts[[#This Row],[First Name]]<>0,ROW()-1,"") -> 27 | B28: אנאי | C28: גרין | D28: Oparations | F28: anai@lumiweave.com | H28: Lead | I28: רשהח"ד 2025 | K28: {=IFERROR(LOOKUP(2,1/('Outreach Log'!$C$2:$C$9998=F28),'Outreach Log'!$B$2:$B$9998),"")} | L28: =IFERROR(INDEX('Outreach Log'!$F:$F,MATCH(TEXT(K28,"YYYY-MM-DD")&F28,'Outreach Log'!$L:$L,0)),"") | M28: =IFERROR(HYPERLINK("#'Outreach Log'!A"&MATCH(TEXT(K28,"YYYY-MM-DD")&F28,'Outreach Log'!$L:$L,0),"→ View"),"—") -> — | N28: =IFERROR(HYPERLINK("#Companies!A"&MATCH(E28,Companies!$B:$B,0),"→ View"),"—") -> —
A29: =IF(tblContacts[[#This Row],[First Name]]<>0,ROW()-1,"") -> 28 | B29: ענאן | C29: סרחאן | F29: anans2861@gmail.com | H29: Lead | I29: AIcademy Webinars | K29: {=IFERROR(LOOKUP(2,1/('Outreach Log'!$C$2:$C$9998=F29),'Outreach Log'!$B$2:$B$9998),"")} | L29: =IFERROR(INDEX('Outreach Log'!$F:$F,MATCH(TEXT(K29,"YYYY-MM-DD")&F29,'Outreach Log'!$L:$L,0)),"") | M29: =IFERROR(HYPERLINK("#'Outreach Log'!A"&MATCH(TEXT(K29,"YYYY-MM-DD")&F29,'Outreach Log'!$L:$L,0),"→ View"),"—") -> — | N29: =IFERROR(HYPERLINK("#Companies!A"&MATCH(E29,Companies!$B:$B,0),"→ View"),"—") -> —
A30: =IF(tblContacts[[#This Row],[First Name]]<>0,ROW()-1,"") -> 29 | B30: אריאל | C30: גיספאן | D30: מפתח אלגוריתמים | E30: אמנדו | F30: ariel.gispan@mail.huji.ac.il | H30: Lead | I30: Webinars 2.26 | K30: {=IFERROR(LOOKUP(2,1/('Outreach Log'!$C$2:$C$9998=F30),'Outreach Log'!$B$2:$B$9998),"")} -> 46126 | L30: =IFERROR(INDEX('Outreach Log'!$F:$F,MATCH(TEXT(K30,"YYYY-MM-DD")&F30,'Outreach Log'!$L:$L,0)),"") -> Email | M30: =IFERROR(HYPERLINK("#'Outreach Log'!A"&MATCH(TEXT(K30,"YYYY-MM-DD")&F30,'Outreach Log'!$L:$L,0),"→ View"),"—") -> → View | N30: =IFERROR(HYPERLINK("#Companies!A"&MATCH(E30,Companies!$B:$B,0),"→ View"),"—") -> → View
A31: =IF(tblContacts[[#This Row],[First Name]]<>0,ROW()-1,"") -> 30 | B31: אריאל | C31: פופר | E31: סולידטי טכנולוגיות בע"מ | F31: ariel@solidt-tech.com | H31: Lead | I31: רשהח"ד 2025 | K31: {=IFERROR(LOOKUP(2,1/('Outreach Log'!$C$2:$C$9998=F31),'Outreach Log'!$B$2:$B$9998),"")} | L31: =IFERROR(INDEX('Outreach Log'!$F:$F,MATCH(TEXT(K31,"YYYY-MM-DD")&F31,'Outreach Log'!$L:$L,0)),"") | M31: =IFERROR(HYPERLINK("#'Outreach Log'!A"&MATCH(TEXT(K31,"YYYY-MM-DD")&F31,'Outreach Log'!$L:$L,0),"→ View"),"—") -> — | N31: =IFERROR(HYPERLINK("#Companies!A"&MATCH(E31,Companies!$B:$B,0),"→ View"),"—") -> → View
A32: =IF(tblContacts[[#This Row],[First Name]]<>0,ROW()-1,"") -> 31 | B32: אריק | C32: חן | E32: ס.פ. ספירפוינט בע"מ | F32: arik@sphere-point.com | H32: Lead | I32: רשהח"ד 2025 | K32: {=IFERROR(LOOKUP(2,1/('Outreach Log'!$C$2:$C$9998=F32),'Outreach Log'!$B$2:$B$9998),"")} | L32: =IFERROR(INDEX('Outreach Log'!$F:$F,MATCH(TEXT(K32,"YYYY-MM-DD")&F32,'Outreach Log'!$L:$L,0)),"") | M32: =IFERROR(HYPERLINK("#'Outreach Log'!A"&MATCH(TEXT(K32,"YYYY-MM-DD")&F32,'Outreach Log'!$L:$L,0),"→ View"),"—") -> — | N32: =IFERROR(HYPERLINK("#Companies!A"&MATCH(E32,Companies!$B:$B,0),"→ View"),"—") -> → View
A33: =IF(tblContacts[[#This Row],[First Name]]<>0,ROW()-1,"") -> 32 | B33: ארתור | C33: רבנר | E33: הפירוויז'ן בע"מ | F33: arthur@hypervision.ai | H33: Lead | I33: רשהח"ד 2025 | K33: {=IFERROR(LOOKUP(2,1/('Outreach Log'!$C$2:$C$9998=F33),'Outreach Log'!$B$2:$B$9998),"")} | L33: =IFERROR(INDEX('Outreach Log'!$F:$F,MATCH(TEXT(K33,"YYYY-MM-DD")&F33,'Outreach Log'!$L:$L,0)),"") | M33: =IFERROR(HYPERLINK("#'Outreach Log'!A"&MATCH(TEXT(K33,"YYYY-MM-DD")&F33,'Outreach Log'!$L:$L,0),"→ View"),"—") -> — | N33: =IFERROR(HYPERLINK("#Companies!A"&MATCH(E33,Companies!$B:$B,0),"→ View"),"—") -> → View
A34: =IF(tblContacts[[#This Row],[First Name]]<>0,ROW()-1,"") -> 33 | B34: אסף | C34: שפי | E34: אקסיומה רובוטיקס בע"מ | F34: asaf@axioma-in.com | H34: Lead | I34: רשהח"ד 2025 | K34: {=IFERROR(LOOKUP(2,1/('Outreach Log'!$C$2:$C$9998=F34),'Outreach Log'!$B$2:$B$9998),"")} | L34: =IFERROR(INDEX('Outreach Log'!$F:$F,MATCH(TEXT(K34,"YYYY-MM-DD")&F34,'Outreach Log'!$L:$L,0)),"") | M34: =IFERROR(HYPERLINK("#'Outreach Log'!A"&MATCH(TEXT(K34,"YYYY-MM-DD")&F34,'Outreach Log'!$L:$L,0),"→ View"),"—") -> — | N34: =IFERROR(HYPERLINK("#Companies!A"&MATCH(E34,Companies!$B:$B,0),"→ View"),"—") -> → View
A35: =IF(tblContacts[[#This Row],[First Name]]<>0,ROW()-1,"") -> 34 | B35: אסף | C35: אלסיבוני | E35: אלסוויי בע"מ | F35: asaf@elssway.com | H35: Lead | I35: רשהח"ד 2025 | K35: {=IFERROR(LOOKUP(2,1/('Outreach Log'!$C$2:$C$9998=F35),'Outreach Log'!$B$2:$B$9998),"")} -> 46126 | L35: =IFERROR(INDEX('Outreach Log'!$F:$F,MATCH(TEXT(K35,"YYYY-MM-DD")&F35,'Outreach Log'!$L:$L,0)),"") -> Email | M35: =IFERROR(HYPERLINK("#'Outreach Log'!A"&MATCH(TEXT(K35,"YYYY-MM-DD")&F35,'Outreach Log'!$L:$L,0),"→ View"),"—") -> → View | N35: =IFERROR(HYPERLINK("#Companies!A"&MATCH(E35,Companies!$B:$B,0),"→ View"),"—") -> → View
A36: =IF(tblContacts[[#This Row],[First Name]]<>0,ROW()-1,"") -> 35 | B36: אסף | C36: שלו | E36: BIO BARRIER NOSOCOMIAL INFECTIONS PREVENTION LTD | F36: asafshalev@bio-barrier.com | H36: Lead | I36: רשהח"ד 2025 | K36: {=IFERROR(LOOKUP(2,1/('Outreach Log'!$C$2:$C$9998=F36),'Outreach Log'!$B$2:$B$9998),"")} -> 46126 | L36: =IFERROR(INDEX('Outreach Log'!$F:$F,MATCH(TEXT(K36,"YYYY-MM-DD")&F36,'Outreach Log'!$L:$L,0)),"") -> Email | M36: =IFERROR(HYPERLINK("#'Outreach Log'!A"&MATCH(TEXT(K36,"YYYY-MM-DD")&F36,'Outreach Log'!$L:$L,0),"→ View"),"—") -> → View | N36: =IFERROR(HYPERLINK("#Companies!A"&MATCH(E36,Companies!$B:$B,0),"→ View"),"—") -> → View
A37: =IF(tblContacts[[#This Row],[First Name]]<>0,ROW()-1,"") -> 36 | B37: אשר | C37: דהן | E37: וורבל דיוויסס בע"מ | F37: asher.dahan@wearabledevices.co.il | H37: Lead | I37: רשהח"ד 2025 | K37: {=IFERROR(LOOKUP(2,1/('Outreach Log'!$C$2:$C$9998=F37),'Outreach Log'!$B$2:$B$9998),"")} -> 46126 | L37: =IFERROR(INDEX('Outreach Log'!$F:$F,MATCH(TEXT(K37,"YYYY-MM-DD")&F37,'Outreach Log'!$L:$L,0)),"") -> Email | M37: =IFERROR(HYPERLINK("#'Outreach Log'!A"&MATCH(TEXT(K37,"YYYY-MM-DD")&F37,'Outreach Log'!$L:$L,0),"→ View"),"—") -> → View | N37: =IFERROR(HYPERLINK("#Companies!A"&MATCH(E37,Companies!$B:$B,0),"→ View"),"—") -> → View
A38: =IF(tblContacts[[#This Row],[First Name]]<>0,ROW()-1,"") -> 37 | B38: אסף | C38: סופר | E38: טירסיאס | F38: assaf.s@tiresias.co | H38: Lead | I38: רשהח"ד 2025 | K38: {=IFERROR(LOOKUP(2,1/('Outreach Log'!$C$2:$C$9998=F38),'Outreach Log'!$B$2:$B$9998),"")} | L38: =IFERROR(INDEX('Outreach Log'!$F:$F,MATCH(TEXT(K38,"YYYY-MM-DD")&F38,'Outreach Log'!$L:$L,0)),"") | M38: =IFERROR(HYPERLINK("#'Outreach Log'!A"&MATCH(TEXT(K38,"YYYY-MM-DD")&F38,'Outreach Log'!$L:$L,0),"→ View"),"—") -> — | N38: =IFERROR(HYPERLINK("#Companies!A"&MATCH(E38,Companies!$B:$B,0),"→ View"),"—") -> → View
A39: =IF(tblContacts[[#This Row],[First Name]]<>0,ROW()-1,"") -> 38 | B39: אסף | C39: קליין | E39: לימאקה מדיקל בע"מ | F39: assaf@limaca-medical.com | H39: Lead | I39: רשהח"ד 2025 | K39: {=IFERROR(LOOKUP(2,1/('Outreach Log'!$C$2:$C$9998=F39),'Outreach Log'!$B$2:$B$9998),"")} | L39: =IFERROR(INDEX('Outreach Log'!$F:$F,MATCH(TEXT(K39,"YYYY-MM-DD")&F39,'Outreach Log'!$L:$L,0)),"") | M39: =IFERROR(HYPERLINK("#'Outreach Log'!A"&MATCH(TEXT(K39,"YYYY-MM-DD")&F39,'Outreach Log'!$L:$L,0),"→ View"),"—") -> — | N39: =IFERROR(HYPERLINK("#Companies!A"&MATCH(E39,Companies!$B:$B,0),"→ View"),"—") -> → View
A40: =IF(tblContacts[[#This Row],[First Name]]<>0,ROW()-1,"") -> 39 | B40: אבי | C40: בלאו | E40: וויש היר - שמיעה עצמית מדומה בע"מ | F40: avi.blau@gmail.com | H40: Lead | I40: רשהח"ד 2025 | K40: {=IFERROR(LOOKUP(2,1/('Outreach Log'!$C$2:$C$9998=F40),'Outreach Log'!$B$2:$B$9998),"")} | L40: =IFERROR(INDEX('Outreach Log'!$F:$F,MATCH(TEXT(K40,"YYYY-MM-DD")&F40,'Outreach Log'!$L:$L,0)),"") | M40: =IFERROR(HYPERLINK("#'Outreach Log'!A"&MATCH(TEXT(K40,"YYYY-MM-DD")&F40,'Outreach Log'!$L:$L,0),"→ View"),"—") -> — | N40: =IFERROR(HYPERLINK("#Companies!A"&MATCH(E40,Companies!$B:$B,0),"→ View"),"—") -> → View
...

Sheet Outreach Log
A1: # | B1: Interaction Date | C1: Contact Email | D1: Contact Name | E1: Company | F1: Type | G1: Subject / Topic | H1: Owner | I1: Next Action | J1: Next Action Date | K1: Status | L1: _key
A2: =IF(tblOutreachLog[[#This Row],[Interaction Date]]<>0,ROW()-1,"") -> 1 | B2: 46084 | C2: avishai.o@axioma-in.com | D2: =IFERROR(INDEX(Contacts!$B:$B,MATCH(C2,Contacts!$F:$F,0))&" "&INDEX(Contacts!$C:$C,MATCH(C2,Contacts!$F:$F,0)),"") -> אבישי עוז | E2: =IFERROR(INDEX(Contacts!$E:$E,MATCH(C2,Contacts!$F:$F,0)),"") -> Axioma | F2: Email | G2: Outreach | H2: שיר | K2: Done | L2: =TEXT(B2,"YYYY-MM-DD")&C2 -> 2026-03-03avishai.o@axioma-in.com
A3: =IF(tblOutreachLog[[#This Row],[Interaction Date]]<>0,ROW()-1,"") -> 2 | B3: 46084 | C3: avner.fr@gmail.com | D3: =IFERROR(INDEX(Contacts!$B:$B,MATCH(C3,Contacts!$F:$F,0))&" "&INDEX(Contacts!$C:$C,MATCH(C3,Contacts!$F:$F,0)),"") -> אבנר פרייברגר | E3: =IFERROR(INDEX(Contacts!$E:$E,MATCH(C3,Contacts!$F:$F,0)),"") -> Ansora | F3: Email | G3: Outreach | H3: שיר | K3: Done | L3: =TEXT(B3,"YYYY-MM-DD")&C3 -> 2026-03-03avner.fr@gmail.com
A4: =IF(tblOutreachLog[[#This Row],[Interaction Date]]<>0,ROW()-1,"") -> 3 | B4: 46084 | C4: burtliron@gmail.com | D4: =IFERROR(INDEX(Contacts!$B:$B,MATCH(C4,Contacts!$F:$F,0))&" "&INDEX(Contacts!$C:$C,MATCH(C4,Contacts!$F:$F,0)),"") -> לירון בורט | E4: =IFERROR(INDEX(Contacts!$E:$E,MATCH(C4,Contacts!$F:$F,0)),"") -> Wsc sports | F4: Email | G4: Outreach | H4: שיר | K4: Done | L4: =TEXT(B4,"YYYY-MM-DD")&C4 -> 2026-03-03burtliron@gmail.com
A5: =IF(tblOutreachLog[[#This Row],[Interaction Date]]<>0,ROW()-1,"") -> 4 | B5: 46084 | C5: daniel.bernstein@bruker.com | D5: =IFERROR(INDEX(Contacts!$B:$B,MATCH(C5,Contacts!$F:$F,0))&" "&INDEX(Contacts!$C:$C,MATCH(C5,Contacts!$F:$F,0)),"") -> דניאל ברנסטין | E5: =IFERROR(INDEX(Contacts!$E:$E,MATCH(C5,Contacts!$F:$F,0)),"") -> Bruker | F5: Email | G5: Outreach | H5: שיר | K5: Done | L5: =TEXT(B5,"YYYY-MM-DD")&C5 -> 2026-03-03daniel.bernstein@bruker.com
A6: =IF(tblOutreachLog[[#This Row],[Interaction Date]]<>0,ROW()-1,"") -> 5 | B6: 46084 | C6: dario@thekokomodo.com | D6: =IFERROR(INDEX(Contacts!$B:$B,MATCH(C6,Contacts!$F:$F,0))&" "&INDEX(Contacts!$C:$C,MATCH(C6,Contacts!$F:$F,0)),"") -> דריו בריטל | E6: =IFERROR(INDEX(Contacts!$E:$E,MATCH(C6,Contacts!$F:$F,0)),"") -> Kokomodo | F6: Email | G6: Outreach | H6: שיר | K6: Done | L6: =TEXT(B6,"YYYY-MM-DD")&C6 -> 2026-03-03dario@thekokomodo.com
A7: =IF(tblOutreachLog[[#This Row],[Interaction Date]]<>0,ROW()-1,"") -> 6 | B7: 46084 | C7: dganit@afimilk.com | D7: =IFERROR(INDEX(Contacts!$B:$B,MATCH(C7,Contacts!$F:$F,0))&" "&INDEX(Contacts!$C:$C,MATCH(C7,Contacts!$F:$F,0)),"") -> דגנית סופר | E7: =IFERROR(INDEX(Contacts!$E:$E,MATCH(C7,Contacts!$F:$F,0)),"") -> Afimilk | F7: Email | G7: Outreach | H7: שיר | K7: Done | L7: =TEXT(B7,"YYYY-MM-DD")&C7 -> 2026-03-03dganit@afimilk.com
A8: =IF(tblOutreachLog[[#This Row],[Interaction Date]]<>0,ROW()-1,"") -> 7 | B8: 46084 | C8: dorinar@everafterfoods.com | D8: =IFERROR(INDEX(Contacts!$B:$B,MATCH(C8,Contacts!$F:$F,0))&" "&INDEX(Contacts!$C:$C,MATCH(C8,Contacts!$F:$F,0)),"") -> דורינה רוברמאן | E8: =IFERROR(INDEX(Contacts!$E:$E,MATCH(C8,Contacts!$F:$F,0)),"") -> ever after foods | F8: Email | G8: Outreach | H8: שיר | K8: Done | L8: =TEXT(B8,"YYYY-MM-DD")&C8 -> 2026-03-03dorinar@everafterfoods.com
A9: =IF(tblOutreachLog[[#This Row],[Interaction Date]]<>0,ROW()-1,"") -> 8 | B9: 46084 | C9: erez@sofwave.com | D9: =IFERROR(INDEX(Contacts!$B:$B,MATCH(C9,Contacts!$F:$F,0))&" "&INDEX(Contacts!$C:$C,MATCH(C9,Contacts!$F:$F,0)),"") -> ארז פניר | E9: =IFERROR(INDEX(Contacts!$E:$E,MATCH(C9,Contacts!$F:$F,0)),"") -> סופוויב | F9: Email | G9: Outreach | H9: שיר | K9: Done | L9: =TEXT(B9,"YYYY-MM-DD")&C9 -> 2026-03-03erez@sofwave.com
A10: =IF(tblOutreachLog[[#This Row],[Interaction Date]]<>0,ROW()-1,"") -> 9 | B10: 46084 | C10: gal@emotionlogic.ai | D10: =IFERROR(INDEX(Contacts!$B:$B,MATCH(C10,Contacts!$F:$F,0))&" "&INDEX(Contacts!$C:$C,MATCH(C10,Contacts!$F:$F,0)),"") -> גל אולבסון | E10: =IFERROR(INDEX(Contacts!$E:$E,MATCH(C10,Contacts!$F:$F,0)),"") -> Emotion Logic | F10: Email | G10: Outreach | H10: שיר | K10: Done | L10: =TEXT(B10,"YYYY-MM-DD")&C10 -> 2026-03-03gal@emotionlogic.ai
A11: =IF(tblOutreachLog[[#This Row],[Interaction Date]]<>0,ROW()-1,"") -> 10 | B11: 46084 | C11: grekov.e@gmail.com | D11: =IFERROR(INDEX(Contacts!$B:$B,MATCH(C11,Contacts!$F:$F,0))&" "&INDEX(Contacts!$C:$C,MATCH(C11,Contacts!$F:$F,0)),"") -> יוג'ין גרקו | E11: =IFERROR(INDEX(Contacts!$E:$E,MATCH(C11,Contacts!$F:$F,0)),"") -> InFocus | F11: Email | G11: Outreach | H11: שיר | K11: Done | L11: =TEXT(B11,"YYYY-MM-DD")&C11 -> 2026-03-03grekov.e@gmail.com
A12: =IF(tblOutreachLog[[#This Row],[Interaction Date]]<>0,ROW()-1,"") -> 11 | B12: 46084 | C12: guy@parksharon.co.il | D12: =IFERROR(INDEX(Contacts!$B:$B,MATCH(C12,Contacts!$F:$F,0))&" "&INDEX(Contacts!$C:$C,MATCH(C12,Contacts!$F:$F,0)),"") -> גיא מזרחי | E12: =IFERROR(INDEX(Contacts!$E:$E,MATCH(C12,Contacts!$F:$F,0)),"") -> Park Ariel Sharon | F12: Email | G12: Outreach | H12: שיר | K12: Done | L12: =TEXT(B12,"YYYY-MM-DD")&C12 -> 2026-03-03guy@parksharon.co.il
A13: =IF(tblOutreachLog[[#This Row],[Interaction Date]]<>0,ROW()-1,"") -> 12 | B13: 46084 | C13: idan@driveu.auto | D13: =IFERROR(INDEX(Contacts!$B:$B,MATCH(C13,Contacts!$F:$F,0))&" "&INDEX(Contacts!$C:$C,MATCH(C13,Contacts!$F:$F,0)),"") -> עידן באוקי | E13: =IFERROR(INDEX(Contacts!$E:$E,MATCH(C13,Contacts!$F:$F,0)),"") -> Driveu.auto | F13: Email | G13: Outreach | H13: שיר | K13: Done | L13: =TEXT(B13,"YYYY-MM-DD")&C13 -> 2026-03-03idan@driveu.auto
... A223: =IF(tblOutreachLog[[#This Row],[Interaction Date]]<>0,ROW()-1,"") -> 222 | B223: 46093 | C223: mankal@energy.gov.il | D223: =IFERROR(INDEX(Contacts!$B:$B,MATCH(C223,Contacts!$F:$F,0))&" "&INDEX(Contacts!$C:$C,MATCH(C223,Contacts!$F:$F,0)),"") | E223: =IFERROR(INDEX(Contacts!$E:$E,MATCH(C223,Contacts!$F:$F,0)),"") | F223: Email | G223: CTO invitation - Personal Meeting R&D | H223: Shir | K223: Done | L223: =TEXT(B223,"YYYY-MM-DD")&C223 -> 2026-03-12mankal@energy.gov.il
A224: =IF(tblOutreachLog[[#This Row],[Interaction Date]]<>0,ROW()-1,"") -> 223 | B224: 46096 | C224: uriel@norterra.co.il | D224: =IFERROR(INDEX(Contacts!$B:$B,MATCH(C224,Contacts!$F:$F,0))&" "&INDEX(Contacts!$C:$C,MATCH(C224,Contacts!$F:$F,0)),"") -> אוריאל פרמן | E224: =IFERROR(INDEX(Contacts!$E:$E,MATCH(C224,Contacts!$F:$F,0)),"") -> נורטרה | F224: Email | G224: Schduale meeting with Alex & Yipaht | H224: Shir | I224: Meeting | J224: 46098 | K224: Done | L224: =TEXT(B224,"YYYY-MM-DD")&C224 -> 2026-03-15uriel@norterra.co.il
A225: =IF(tblOutreachLog[[#This Row],[Interaction Date]]<>0,ROW()-1,"") -> 224 | B225: 46104 | C225: ziv@alvox.co.il | D225: =IFERROR(INDEX(Contacts!$B:$B,MATCH(C225,Contacts!$F:$F,0))&" "&INDEX(Contacts!$C:$C,MATCH(C225,Contacts!$F:$F,0)),"") -> זיו הלר | E225: =IFERROR(INDEX(Contacts!$E:$E,MATCH(C225,Contacts!$F:$F,0)),"") -> Alvox Bio | F225: Email | G225: גיוס, A_I, פיתוח לתהליכי ייצור | H225: Shir | I225: Review | J225: 46204 | K225: Done | L225: =TEXT(B225,"YYYY-MM-DD")&C225 -> 2026-03-23ziv@alvox.co.il
A226: =IF(tblOutreachLog[[#This Row],[Interaction Date]]<>0,ROW()-1,"") -> 225 | B226: 46104 | C226: liat@alvox.co.il | D226: =IFERROR(INDEX(Contacts!$B:$B,MATCH(C226,Contacts!$F:$F,0))&" "&INDEX(Contacts!$C:$C,MATCH(C226,Contacts!$F:$F,0)),"") -> ליאת שלומי | E226: =IFERROR(INDEX(Contacts!$E:$E,MATCH(C226,Contacts!$F:$F,0)),"") -> Alvox Bio | F226: Email | G226: גיוס, A_I, פיתוח לתהליכי ייצור | H226: Shir | I226: Review | J226: 46204 | K226: Done | L226: =TEXT(B226,"YYYY-MM-DD")&C226 -> 2026-03-23liat@alvox.co.il
A227: =IF(tblOutreachLog[[#This Row],[Interaction Date]]<>0,ROW()-1,"") -> 226 | B227: 46104 | C227: yarons@bduk-tx.com | D227: =IFERROR(INDEX(Contacts!$B:$B,MATCH(C227,Contacts!$F:$F,0))&" "&INDEX(Contacts!$C:$C,MATCH(C227,Contacts!$F:$F,0)),"") -> ירון סויסה | E227: =IFERROR(INDEX(Contacts!$E:$E,MATCH(C227,Contacts!$F:$F,0)),"") -> בדיוק תרפויטיקה | F227: Email | G227: גיוס, A_I, פיתוח לתהליכי ייצור | H227: Shir | I227: לא רלוונטי | K227: Done | L227: =TEXT(B227,"YYYY-MM-DD")&C227 -> 2026-03-23yarons@bduk-tx.com
A228: =IF(tblOutreachLog[[#This Row],[Interaction Date]]<>0,ROW()-1,"") -> 227 | B228: 46104 | C228: adi@birad.biz | D228: =IFERROR(INDEX(Contacts!$B:$B,MATCH(C228,Contacts!$F:$F,0))&" "&INDEX(Contacts!$C:$C,MATCH(C228,Contacts!$F:$F,0)),"") -> עדי בן עמרם | E228: =IFERROR(INDEX(Contacts!$E:$E,MATCH(C228,Contacts!$F:$F,0)),"") -> ביראד- חברה למחקר ופיתוח בע"מ | F228: Email | G228: ייעוץ ופיתוח בהעברה ממחקר לישום, כלי AI | H228: Shir | K228: Done | L228: =TEXT(B228,"YYYY-MM-DD")&C228 -> 2026-03-23adi@birad.biz
A229: =IF(tblOutreachLog[[#This Row],[Interaction Date]]<>0,ROW()-1,"") -> 228 | B229: 46104 | C229: rotem.golan@claro3d.com | D229: =IFERROR(INDEX(Contacts!$B:$B,MATCH(C229,Contacts!$F:$F,0))&" "&INDEX(Contacts!$C:$C,MATCH(C229,Contacts!$F:$F,0)),"") -> רותם גולן | E229: =IFERROR(INDEX(Contacts!$E:$E,MATCH(C229,Contacts!$F:$F,0)),"") -> קלארו 3 די ננו פרינתינג סולושינס | F229: Email | G229: R&D | H229: Shir | I229: לא רלוונטי | K229: Done | L229: =TEXT(B229,"YYYY-MM-DD")&C229 -> 2026-03-23rotem.golan@claro3d.com
A230: =IF(tblOutreachLog[[#This Row],[Interaction Date]]<>0,ROW()-1,"") -> 229 | B230: 46104 | C230: hagit.alon@gmail.com | D230: =IFERROR(INDEX(Contacts!$B:$B,MATCH(C230,Contacts!$F:$F,0))&" "&INDEX(Contacts!$C:$C,MATCH(C230,Contacts!$F:$F,0)),"") -> חגית אלון | E230: =IFERROR(INDEX(Contacts!$E:$E,MATCH(C230,Contacts!$F:$F,0)),"") -> 0 | F230: Email | G230: ייעוץ לפרוטפוליו | H230: Shir | I230: לא רלוונטי | K230: Done | L230: =TEXT(B230,"YYYY-MM-DD")&C230 -> 2026-03-23hagit.alon@gmail.com
A231: =IF(tblOutreachLog[[#This Row],[Interaction Date]]<>0,ROW()-1,"") -> 230 | B231: 46099 | C231: Daya@taryag-group.com | D231: =IFERROR(INDEX(Contacts!$B:$B,MATCH(C231,Contacts!$F:$F,0))&" "&INDEX(Contacts!$C:$C,MATCH(C231,Contacts!$F:$F,0)),"") -> דיה לטוין | E231: =IFERROR(INDEX(Contacts!$E:$E,MATCH(C231,Contacts!$F:$F,0)),"") -> תריג עיקור ומעבדות בעמ | F231: Meeting | G231: Yiphat+Alex+Daya | H231: Yiphat | I231: לשלוח פרטים על אורוול | J231: 46105 | K231: In Progress | L231: =TEXT(B231,"YYYY-MM-DD")&C231 -> 2026-03-18Daya@taryag-group.com
A232: =IF(tblOutreachLog[[#This Row],[Interaction Date]]<>0,ROW()-1,"") -> 231 | B232: 46104 | C232: ido.a@ardena-labs.com | D232: =IFERROR(INDEX(Contacts!$B:$B,MATCH(C232,Contacts!$F:$F,0))&" "&INDEX(Contacts!$C:$C,MATCH(C232,Contacts!$F:$F,0)),"") -> עידו ענתבי | E232: =IFERROR(INDEX(Contacts!$E:$E,MATCH(C232,Contacts!$F:$F,0)),"") -> ארדנה מעבדות | F232: Email | G232: גיוס, A_I, פיתוח לתהליכי ייצור | H232: Shir | I232: Meeting | J232: 46107 | K232: In Progress | L232: =TEXT(B232,"YYYY-MM-DD")&C232 -> 2026-03-23ido.a@ardena-labs.com
A233: =IF(tblOutreachLog[[#This Row],[Interaction Date]]<>0,ROW()-1,"") -> 232 | B233: 46104 | C233: ronen.nakash@birad.biz | D233: =IFERROR(INDEX(Contacts!$B:$B,MATCH(C233,Contacts!$F:$F,0))&" "&INDEX(Contacts!$C:$C,MATCH(C233,Contacts!$F:$F,0)),"") -> רונן נקש | E233: =IFERROR(INDEX(Contacts!$E:$E,MATCH(C233,Contacts!$F:$F,0)),"") -> ביראד- חברה למחקר ופיתוח בע"מ | F233: Email | G233: תודה על מענה, הצעה לפגישה | H233: Shir | I233: סטטוס | J233: 46147 | K233: In Progress | L233: =TEXT(B233,"YYYY-MM-DD")&C233 -> 2026-03-23ronen.nakash@birad.biz
A234: =IF(tblOutreachLog[[#This Row],[Interaction Date]]<>0,ROW()-1,"") -> 233 | B234: 46106 | C234: yigal@genopore.com | D234: =IFERROR(INDEX(Contacts!$B:$B,MATCH(C234,Contacts!$F:$F,0))&" "&INDEX(Contacts!$C:$C,MATCH(C234,Contacts!$F:$F,0)),"") -> יגאל ליבה | E234: =IFERROR(INDEX(Contacts!$E:$E,MATCH(C234,Contacts!$F:$F,0)),"") -> ג'נופור | F234: Email | G234: תודה על מענה, הצעה לפגישה | H234: Shir | I234: סטטוס | J234: 46157 | K234: In Progress | L234: =TEXT(B234,"YYYY-MM-DD")&C234 -> 2026-03-25yigal@genopore.com
A235: =IF(tblOutreachLog[[#This Row],[Interaction Date]]<>0,ROW()-1,"") -> 234 | B235: 46096 | C235: maya@innoafrica.org | D235: =IFERROR(INDEX(Contacts!$B:$B,MATCH(C235,Contacts!$F:$F,0))&" "&INDEX(Contacts!$C:$C,MATCH(C235,Contacts!$F:$F,0)),"") -> מיה איל | E235: =IFERROR(INDEX(Contacts!$E:$E,MATCH(C235,Contacts!$F:$F,0)),"") -> innovation Africa | F235: Email | G235: בקשה לפגישה עם יפעת | H235: Shir | I235: סטטוס | J235: 46099 | K235: Waiting of answer | L235: =TEXT(B235,"YYYY-MM-DD")&C235 -> 2026-03-15maya@innoafrica.org
A236: =IF(tblOutreachLog[[#This Row],[Interaction Date]]<>0,ROW()-1,"") -> 235 | B236: 46096 | C236: nickyl@mor.org.il | D236: =IFERROR(INDEX(Contacts!$B:$B,MATCH(C236,Contacts!$F:$F,0))&" "&INDEX(Contacts!$C:$C,MATCH(C236,Contacts!$F:$F,0)),"") -> ניקי | E236: =IFERROR(INDEX(Contacts!$E:$E,MATCH(C236,Contacts!$F:$F,0)),"") -> מור - מנכל מכון מור | F236: Email | G236: בקשה פגישה | H236: Shir | I236: סטטוס | J236: 46099 | K236: Waiting of answer | L236: =TEXT(B236,"YYYY-MM-DD")&C236 -> 2026-03-15nickyl@mor.org.il
A237: =IF(tblOutreachLog[[#This Row],[Interaction Date]]<>0,ROW()-1,"") -> 236 | B237: 46096 | C237: Daya@taryag-group.com | D237: =IFERROR(INDEX(Contacts!$B:$B,MATCH(C237,Contacts!$F:$F,0))&" "&INDEX(Contacts!$C:$C,MATCH(C237,Contacts!$F:$F,0)),"") -> דיה לטוין | E237: =IFERROR(INDEX(Contacts!$E:$E,MATCH(C237,Contacts!$F:$F,0)),"") -> תריג עיקור ומעבדות בעמ | F237: Email | G237: Scheduale meeting with Alex & Yipaht | H237: Shir | I237: סטטוס | J237: 46096 | K237: Waiting of answer | L237: =TEXT(B237,"YYYY-MM-DD")&C237 -> 2026-03-15Daya@taryag-group.com
A238: =IF(tblOutreachLog[[#This Row],[Interaction Date]]<>0,ROW()-1,"") -> 237 | B238: 46098 | C238: uriel@norterra.co.il | D238: =IFERROR(INDEX(Contacts!$B:$B,MATCH(C238,Contacts!$F:$F,0))&" "&INDEX(Contacts!$C:$C,MATCH(C238,Contacts!$F:$F,0)),"") -> אוריאל פרמן | E238: =IFERROR(INDEX(Contacts!$E:$E,MATCH(C238,Contacts!$F:$F,0)),"") -> נורטרה | F238: Email | G238: Neat Intro & Oravel & AI | H238: Yiphat | I238: סטטוס | J238: 46143 | K238: Waiting of answer | L238: =TEXT(B238,"YYYY-MM-DD")&C238 -> 2026-03-17uriel@norterra.co.il
A239: =IF(tblOutreachLog[[#This Row],[Interaction Date]]<>0,ROW()-1,"") -> 238 | B239: 46104 | C239: pninit@biotization.com | D239: =IFERROR(INDEX(Contacts!$B:$B,MATCH(C239,Contacts!$F:$F,0))&" "&INDEX(Contacts!$C:$C,MATCH(C239,Contacts!$F:$F,0)),"") -> פנינית גלבוע טל | E239: =IFERROR(INDEX(Contacts!$E:$E,MATCH(C239,Contacts!$F:$F,0)),"") -> Biotization | F239: Email | G239: R&D, כלי AI | H239: Shir | K239: Done | L239: =TEXT(B239,"YYYY-MM-DD")&C239 -> 2026-03-23pninit@biotization.com
A240: =IF(tblOutreachLog[[#This Row],[Interaction Date]]<>0,ROW()-1,"") -> 239 | B240: 46104 | C240: gidi@hemispheric.ai | D240: =IFERROR(INDEX(Contacts!$B:$B,MATCH(C240,Contacts!$F:$F,0))&" "&INDEX(Contacts!$C:$C,MATCH(C240,Contacts!$F:$F,0)),"") -> גידי ליטווין | E240: =IFERROR(INDEX(Contacts!$E:$E,MATCH(C240,Contacts!$F:$F,0)),"") -> HEMISPHERIC AI | F240: Email | G240: גיוס, A_I | H240: Shir | K240: Done | L240: =TEXT(B240,"YYYY-MM-DD")&C240 -> 2026-03-23gidi@hemispheric.ai
A241: =IF(tblOutreachLog[[#This Row],[Interaction Date]]<>0,ROW()-1,"") -> 240 | B241: 46104 | C241: hagai@hemispheric.ai | D241: =IFERROR(INDEX(Contacts!$B:$B,MATCH(C241,Contacts!$F:$F,0))&" "&INDEX(Contacts!$C:$C,MATCH(C241,Contacts!$F:$F,0)),"") -> חגי לאלאזר | E241: =IFERROR(INDEX(Contacts!$E:$E,MATCH(C241,Contacts!$F:$F,0)),"") -> HEMISPHERIC AI | F241: Email | G241: גיוס, A_I | H241: Shir | K241: Done | L241: =TEXT(B241,"YYYY-MM-DD")&C241 -> 2026-03-23hagai@hemispheric.ai
A242: =IF(tblOutreachLog[[#This Row],[Interaction Date]]<>0,ROW()-1,"") -> 241 | B242: 46104 | C242: talelazar@siopt.ai | D242: =IFERROR(INDEX(Contacts!$B:$B,MATCH(C242,Contacts!$F:$F,0))&" "&INDEX(Contacts!$C:$C,MATCH(C242,Contacts!$F:$F,0)),"") -> טל אלעזר | E242: =IFERROR(INDEX(Contacts!$E:$E,MATCH(C242,Contacts!$F:$F,0)),"") -> SiOpt Systems | F242: Email | G242: גיוס, A_I | H242: Shir | K242: Done | L242: =TEXT(B242,"YYYY-MM-DD")&C242 -> 2026-03-23talelazar@siopt.ai
A243: =IF(tblOutreachLog[[#This Row],[Interaction Date]]<>0,ROW()-1,"") -> 242 | B243: 46104 | C243: segeva@tiki100.com | D243: =IFERROR(INDEX(Contacts!$B:$B,MATCH(C243,Contacts!$F:$F,0))&" "&INDEX(Contacts!$C:$C,MATCH(C243,Contacts!$F:$F,0)),"") -> אבי שגב | E243: =IFERROR(INDEX(Contacts!$E:$E,MATCH(C243,Contacts!$F:$F,0)),"") -> TIKI100 | F243: Email | G243: R&D | H243: Shir | I243: הצעת מחיר | J243: 46115 | K243: Waiting of answer | L243: =TEXT(B243,"YYYY-MM-DD")&C243 -> 2026-03-23segeva@tiki100.com
A244: =IF(tblOutreachLog[[#This Row],[Interaction Date]]<>0,ROW()-1,"") -> 243 | B244: 46104 | C244: bgn@in.bgu | D244: =IFERROR(INDEX(Contacts!$B:$B,MATCH(C244,Contacts!$F:$F,0))&" "&INDEX(Contacts!$C:$C,MATCH(C244,Contacts!$F:$F,0)),"") | E244: =IFERROR(INDEX(Contacts!$E:$E,MATCH(C244,Contacts!$F:$F,0)),"") | F244: Email | G244: ייעוץ ופיתוח בהעברה ממחקר לישום, כלי AI | H244: Shir | K244: Done | L244: =TEXT(B244,"YYYY-MM-DD")&C244 -> 2026-03-23bgn@in.bgu
A245: =IF(tblOutreachLog[[#This Row],[Interaction Date]]<>0,ROW()-1,"") -> 244 | B245: 46104 | C245: talor@ehealthventures.com | D245: =IFERROR(INDEX(Contacts!$B:$B,MATCH(C245,Contacts!$F:$F,0))&" "&INDEX(Contacts!$C:$C,MATCH(C245,Contacts!$F:$F,0)),"") -> תלאור סקס | E245: =IFERROR(INDEX(Contacts!$E:$E,MATCH(C245,Contacts!$F:$F,0)),"") -> אי אייץ' וי ישראל | F245: Email | G245: ייעוץ לפרוטפוליו | H245: Shir | K245: Done | L245: =TEXT(B245,"YYYY-MM-DD")&C245 -> 2026-03-23talor@ehealthventures.com
A246: =IF(tblOutreachLog[[#This Row],[Interaction Date]]<>0,ROW()-1,"") -> 245 | B246: 46104 | C246: ophir@ehealthventures.com | D246: =IFERROR(INDEX(Contacts!$B:$B,MATCH(C246,Contacts!$F:$F,0))&" "&INDEX(Contacts!$C:$C,MATCH(C246,Contacts!$F:$F,0)),"") -> אופיר שהף | E246: =IFERROR(INDEX(Contacts!$E:$E,MATCH(C246,Contacts!$F:$F,0)),"") -> אי אייץ' וי ישראל | F246: Email | G246: ייעוץ לפרוטפוליו | H246: Shir | K246: Done | L246: =TEXT(B246,"YYYY-MM-DD")&C246 -> 2026-03-23ophir@ehealthventures.com
